Workbook

Sheet Draft Student-facing 25-26 CW1
B1: Task 1: Problem identification [20 /100 Marks] | AA1: Task 2a: Implementing Dropout, Weight Penalty, Label Smoothing [30 /100 Marks] | AS1: Task 2b: Mitigating the problem (with Dropout and Weight Penalty, Soft Labels, custom activation function) [35 /100 Marks] | BT1: Task 3: Literature Review and Conclusions [15 /100 Marks]
B2: Question 1: Explain what these figures (Figures 1.a and 1.b) contain and how the curves evolve, and spot where overfitting occurs. Reason based on the min/max points and velocities (direction and magnitude of change) of the accuracy and error curves. | G2: Question Table 1 | H2: Question Figure 2 | I2: Question 2: Present your network width experiment results by using the relevant figure and table. [see also Question 3] | K2: Question 3 [Marking 2 & 3 together, doesn't matter which answer has the info]: Discuss whether varying width affects the results in a consistent way, and whether the results are expected and match well with the prior knowledge (by which we mean your expectations as are formed from the relevant Theory and literature) | Q2: Question Table 2 | R2: Question Figure 3 | S2: Question 4: Present your network depth experiment results by using the relevant figure and table [see Question 5] | U2: Question 5: [Marking 4 & 5 together, doesn't matter which answer has the info]: Discuss whether varying depth affects the results in a consistent way, and whether the results are expected and match well with the prior knowledge (by which we mean your expectations as are formed from the relevant Theory and literature) | AA2: Code Marking: | AL2: Question 6: Explain how one could use a combination of L1 and L2 regularisation. Discuss any potential benefits of this approach. Present an equation for this combined loss function and explain all relevant variables and hyperparameters | AS2: Question Table 3 | AT2: Question Figure 4 | AU2: Question Table 4 | AV2: Question Figure 5 | AW2: Question 7: Assume you had a limited experiment budget for exactly 4 experiment runs dedicated to testing the effectiveness of your proposed combination of L1 and L2 Regularization in Section 3.2.1. Argue for which 4 configurations to run based on any previous results or other information you consider relevant. Run those experiments and add the results in Table 4 and Figure 5 (you will then discuss those results alongside all others in the next question below). (Even if you have not managed to implement your L1 and L2 combination; still argue based on your proposed approach). | BC2: Question 8: Explain the experimental details (e.g. hyperparameters), discuss the results in terms of their generalisation performance and overfitting. Select and test the best performing model as part of this analysis. | BM2: Question Figure 6 | BN2: Question 9: A colleague proposed using a custom activation function (which can be identified as Custom_ActivationLayer() in your Coursework_1.ipynb notebook and the mlp package). Run the prepared experiment in the "Problematic Training" cell in your Coursework_1.ipynb notebook, and display the results in Figure 6. Analyse the results. Is the model overfitting? Explain the cause of the problematic performance of the model? | BT2: Question 10: Briefly draw your conclusions based on the results from the previous sections (what are the take-away messages?), discussing them in the context of the overall literature, and conclude your report with a recommendation for future directions
A3: Checks -> | B3: "Training accuracy increases." | C3: "Validation accuracy caps/reaches maximum/stops increasing..." | D3: "...around/at epoch ##" [have quick glimpse this is very roughly correct for their Figure 1.a]. | E3: States that there is an increase of the generalisation gap... | F3: ... and points out where that is, using the graph. [quick look at Figure 1.b; it should be around the same epoch as for the accuracy figure]. | G3: Table 1 - It has been filled and results roughly around what we would expect (not obviously misacalucated or the result of a broken model) | H3: Figure 2 - Requested graphs are present and roughly as expected (ran for enough time-steps and not indicative of a broken model or run). | I3: Correctly states which models have been overfit... | J3: ... and points to evidence in the figure for the specific training instance/models that overfit. [This can be a statement on which models have their generalisation gap increasing or pointing out specific values on the figures]. [check Table 1 and Figure 2 that their statements are mostly concistent with their results]. | K3: Correctly discusses the trend (or lack thereof) of the generalisation gap/overfitting as hyperparamer values change. [check Table 1 and Figure 2 in case something else holds in the students case; what matters here is consistency with their own results]. | L3: Points out the model with the best validation accuracy (from this series). | M3: Points out the model that overfits less (from this series). [these are not necessarily the same, so the student should not just say "this model is best". If they simply state this charitably assume they are talking about overfitting]. | N3: Uses relevant literature to form their expectations of how the experiment will/should have or would have been expected to turn out. | O3: Forms expectations via (reasonably) arguing based on model capacity. | P3: Goes beyond these expectations in successfully addressing Questions 2&3 (not simply added information but either things that add to the argument or an excellent delivery of previous points). | Q3: Table 2 - It has been filled and results roughly around what we would expect (not obviously misacalucated or the result of a broken model) | R3: Figure 3 - Requested graphs are present and roughly as expected (ran for enough time-steps and not indicative of a broken model or run). | S3: Correctly states which models have been overfit... | T3: ... and points to evidence in the figure for the specific training instance/models that overfit. [This can be a statement on which models have their generalisation gap increasing or pointing out specific values on the figures]. [check Table 2 and Figure 3 that their statements are mostly concistent with their results]. | U3: Discusses the trend (or lack thereof) of the generalisation gap/overfitting as hyperparamer values change. [check Table 2 and Figure 3 in case something else holds in the students case; what matters here is consistency with their own results]. | V3: Points out the model with the best validation accuracy (from this series). | W3: Points out the model that overfits less (from this series). [these are not necessarily the same, so the student should not just say "this model is best". If they simply state this charitably assume they are talking about overfitting]. | X3: Uses relevant literature to form their expectations of how the experiment will/should have or would have been expected to turn out. | Y3: Forms expectations via (reasonably) arguing based on model capacity. | Z3: Goes beyond these expectations in successfully addressing Questions 4&5 (not simply added information but either things that add to the argument or an excellent delivery of previous points). | AA3: Check: Code exists | AB3: Check: Test package exists | AC3: Forward Propagation for DropoutLayer [auto-marked] | AD3: Backwards Propagation for DropoutLayer [auto-marked] | AE3: Call function for L1Penalty [auto-marked] | AF3: Grad check for L1Penalty [auto-marked] | AG3: Call func for L2Penalty [auto-marked] | AH3: Grad check for L2Penalty [auto-marked] | AI3: Label Smoothing correctly implemented | AJ3: L1 & L2 mix is implemented (any form) | AK3: L1 & L2 mix implementation is of the described function in the answer to Question 6 | AL3: State we could add terms with L1 and L2 weights in the cost function. | AM3: Give an equation for the new penalty term. [e.g.: penalty = alpha * l1_penalty + (1 – alpha) * l2_penalty]. | AN3: Identify a relevant approach in the literature [this requires a reference]. | AO3: Mention this adds an extra hyperparameter. [explicit statement, not just adding to equation] | AP3: ... and explain the importance of that. | AQ3: Explain the effect this L1&L2 regularisation mix has on training. Why might someone use this setup over a plain L1 or L2 penalty? | AR3: Goes beyond these expectations in successfully addressing Questions 6 (not simply added information but either things that add to the argument or an excellent delivery of previous points). | AS3: Table 3 - It has been filled and results roughly around what we would expect (not obviously misacalucated or the result of a broken model) | AT3: Figure 4 - Requested graphs are present and roughly as expected (ran for enough time-steps and not indicative of a broken model or run). | AU3: Table 4 - It has been filled and results roughly around what we would expect (not obviously misacalucated or the result of a broken model) | AV3: Figure 5 - Requested graphs are present and roughly as expected (ran for enough time-steps and not indicative of a broken model or run). | AW3: Stays within the expected 4 different experiment setups (as expressed in terms of what hyperparameters they pick; but it can also be a change in achitecture or similar if they want) [Anything more than that is ignored; first 4 configurations are looked at along the relevant argumentation] | AX3: An attempt (at minimum) to specify a question or what they would be trying to figure out from these experiments. | AY3: ... and that question goes beyond trying to see which hyperparameter configurations would work best. [Giving a bit more structure, like "Do smaller values of one hyperparameter value work better with larger values of this other one" is sufficient]. | AZ3: ... and successfully argues for the value of this question (that goes beyond a simple hyperparameter configuration) | BA3: Successfully argues for how the proposed experiments will help address the question. [consider using evidence from the literature and previous experimental results in this coursework] | BB3: Does an exceptional job delivering an argument or surprises positively with its insight. | BC3: All regularisation methods can help with overfitting/overtraining for some hyper parameter value. [However, the point can be given by stating that this is in fact not the case. Check Table 3. Consistency with presented results is what matters here]. | BD3: There are regularisation (hyper parameter) values for which performance degrades significantly. [If however, we have the case as in the previous point where all results are bad, this point is replaced with a need to discuss the expectation that some hyper parameter values make sense to reduce performance but others do not]. | BE3: Correctly state (based on their data) which model from the single-regularisation-approach performed best, based on validation accuracy (or error if they have that). | BF3: Correctly state (based on their data) which model from the single-regularisation-approach performed best in terms of generalisation gap / not overfitting (the smaller the better). | BG3: Compare the performance of baseline with softlabelled baseline. | BH3: Compare performance with regularisation of any kind (any model from any set up or make a general comparison) with that of the baseline's performance. | BI3: Make a reasonable (based on their evidence; see Figure 4 and Table 3) statement on whether overfitting is being tackled by some, any, or all of the approaches. | BJ3: Note some, valid based on their results, relationship between best performing (in terms of accuracy) model and the respective generalisation gap. | BK3: Run and present test results for the best performing model in terms of accuracy and/or overfitting. [Note that because they were given results for most models, they might have to train the best model before they can test. Don't penalise this, but check that they report test results. Same with next point]. | BL3: Goes beyond these expectations in successfully addressing Question 8 (not simply added information but either things that add to the argument or an excellent delivery of previous points). | BM3: Figure 6 - Requested graphs are present and roughly as expected (ran for enough time-steps and not indicative of a broken model or run). | BN3: Clearly states whether the model is overfitting or underfitting, referring to the correct visual evidence from Figure 6. | BO3: Accurately names or describes the type of training fault observed. [Avoid vague terms like “it’s unstable.”]. | BP3: Correctly identifies what element in the network setup or design is producing the fault. | BQ3: Explains how that element leads to the observed behaviour. | BR3: Discusses how the problem could be addressed. | BS3: Goes beyond these expectations in successfully addressing Question 9 (not simply added information but either things that add to the argument or an excellent delivery of previous points). | BT3: (At least an attempt to) summarise the experiment results | BU3: The sumary effectively conveys the range of things tested | BV3: There is some relevant discussion (not just a mention) on some of the literature cited earlier in the report. | BW3: Results are compared with relevant results in the literature (any literature) | BX3: State whether dropout or L1/L2 helped with overfitting. [not simply giving results that indicate that or say that X model helped; I am looking for a general statement on how the techniques seem to work, based on the results] | BY3: Compare Dropout-only with Weight-only (either or both of L1 and L2) based on the experimental results. | BZ3: Indicate additional (that is: not asked for explicitly in the paper) reasonable alternatives for combatting overfitting | CA3: ... and cite an appropriate paper for that method | CB3: Suggest any reasonable future work (at least incremental, as in "we could also try this") [Answer to Question 7 does not count for this one. You will need something new] | CC3: Effectively make use of the literature in arguing for Future Work | CD3: Explain the relevance of "network capacity" to overfitting. Discussing how both width and depth increase the newtworks size should be treated as equivalent to using the term; then also explain how that affects overfitting. | CE3: You can find one thing that shows quality extra/not anticipated from these points analysis. [Maybe the future work suggestion is particularly interesting or shows good thought, or perhaps there is some further interesting analysis of the experiments, or they attempt a mini comparative review of different approaches using evidence from the literature]
B5: Easy - Pass requires a majority of these points
B6: Medium - Point of Merit | E6: These checks are used to get a good sense of the work. The marker then considers these against the University Common Marking Scheme, looks at the overall work in each Task, and judges the work in accordance. At a minimum, you should expect to meet most Points of Merit to receive a Merit for a Task, and almost all Points of Merit & A Point of Distinction to receive a Distinction for a Task.
B7: Hard - Point of Distinction
E10: Points are NOT equally weighted, and the mark is NOT produced as a linear function of these points.

Sheet Task 2a - Mitigating the Proble
U1: CW1: Roughly 135 hours total marking -> Roughly 30 minutes per report total&averaged
Q2: Yifu 30 hours total (both CW) (max: 6/6/6) (rows 167 - 196) | R2: Pavlos / Hakan (rows 197 -206) | S2: Mantas 40 hours total (both CW) (rows 205-213) | U2: Task 2a: Mitigating the problem with Dropout and Weight Penalty [10 /100 Marks]
Q3: Ronald 30 hours total (both CW) (max: 8/12/10) (rows 137 - 166) | R3: Xiaoliang 60 hours total (both CW) (max: 10/10/20) (rows 7 - 66) | U3: Question 12: Explain how one could use a combination of L1 and L2 regularization. Discuss any potential benefits of this approach. [10 /100 Marks]
Q4: Salvatore 30 hours total (both CW) (max: 15/6/0) (rows 107 - 136) | R4: Hao 40 hours total (both CW) (max: 0/20/20) (rows 67 - 106) | T4: Points -> | U4: They state we could add terms with L1 and L2 weights in the cost function. | V4: They give a rough equation for the new penalty term. [e.g.: penalty = alpha * l1_penalty + (1 – alpha) * l2_penalty]. | W4: They mention Elastic Nets. | X4: They cite: /Hui Zou,Trevor Hastie, Regularization and variable selection via the elastic net/ OR use a another reference defining Elastic nets. | Y4: They mention this adds an extra hyperparameter. [explicit statement, not just adding to equation] | Z4: They state that this might/could/does give us the benefits of both approaches. | AA4: They state that this might not be better in practice, as it introduces an extra hyperparameter. | AB4: Gives any added insight [state what in comments] | AC4: Comments: [point out good insight if relevant point given] & [point out any obvious misunderstanding]
A5: Marker | B5: SUM | C5: COUNT | D5: Total Marks | E5: Basic Sum | F5: Adv. Sum | G5: Expert sum | H5: 20 | I5: 30+ | J5: 40+ | K5: 50+ | L5: 60+ | M5: 70+ | N5: 80+ | O5: 90+ | P5: 100 | Q5: Problem? (comment in cell) | R5: Report missing (1 = missing) | S5: Submission Date | T5: Student UUN | U5: - | W5: -2 | AC5: -3
A6: Example Marker | T6: s####### | U6: 1 | V6: 0 | W6: 1 | X6: 1 | Y6: 0 | Z6: 1 | AA6: 0 | AB6: 0 | AC6: Good that you discuss when one might want to use a combined Loss.
B7: =(SUM(U7:AB7)) -> 5 | C7: =(COUNT(U7:AB7)) -> 8 | D7: =ROUNDUP( MAX( IF(P7,100, IF(O7,80, IF(N7,70, IF(M7,60, IF(L7,55, IF(K7,50, IF(J7,45, IF(I7,35, IF(H7,25, 0))))))))), 100 * B7/C7 ) * 10 / 100,0) -> 7 | E7: =SUM(U7, Z7) -> 2 | F7: =SUM(V7, W7, X7) -> 1 | G7: =SUM(Y7, AA7, AB7) -> 2 | H7: =IF(B7>0,1,0) -> 1 | I7: =IF( B7/C7 > 0.2, 1, IF(E7>0, 1, 0) ) -> 1 | J7: =IF( B7/C7 > 0.4, 1, IF( E7=2, 1, IF(AND(E7>0, OR(F7>0, G7>0)), 1, 0 ) )) -> 1 | K7: =IF(B7/C7 > 0.5, 1, IF( E7=2, 1, IF(AND(E7>0, OR(F7>1, G7>0)), 1, 0 ) )) -> 1 | L7: =IF(B7/C7 > 0.6, 1, IF( AND(E7=2, OR(F7>0, G7>0)), 1, 0 ) ) -> 1 | M7: =IF(B7/C7 > 0.7, 1, IF( AND(E7=2, SUM(F7, G7)>1), 1, 0 ) ) -> 1 | N7: =IF(B7/C7 > 0.8, 1, IF( AND(E7=2, SUM(F7, G7)>3), 1, 0 ) ) -> 0 | O7: =IF(B7/C7 > 0.9, 1, 0) -> 0 | P7: =ROUNDDOWN(B7/C7,0) -> 0 | U7: 1 | V7: 1 | W7: 0 | X7: 0 | Y7: 1 | Z7: 1 | AA7: 1 | AB7: 0
B8: =(SUM(U8:AB8)) -> 2 | C8: =(COUNT(U8:AB8)) -> 8 | D8: =ROUNDUP( MAX( IF(P8,100, IF(O8,80, IF(N8,70, IF(M8,60, IF(L8,55, IF(K8,50, IF(J8,45, IF(I8,35, IF(H8,25, 0))))))))), 100 * B8/C8 ) * 10 / 100,0) -> 5 | E8: =SUM(U8, Z8) -> 1 | F8: =SUM(V8, W8, X8) -> 1 | G8: =SUM(Y8, AA8, AB8) -> 0 | H8: =IF(B8>0,1,0) -> 1 | I8: =IF( B8/C8 > 0.2, 1, IF(E8>0, 1, 0) ) -> 1 | J8: =IF( B8/C8 > 0.4, 1, IF( E8=2, 1, IF(AND(E8>0, OR(F8>0, G8>0)), 1, 0 ) )) -> 1 | K8: =IF(B8/C8 > 0.5, 1, IF( E8=2, 1, IF(AND(E8>0, OR(F8>1, G8>0)), 1, 0 ) )) -> 0 | L8: =IF(B8/C8 > 0.6, 1, IF( AND(E8=2, OR(F8>0, G8>0)), 1, 0 ) ) -> 0 | M8: =IF(B8/C8 > 0.7, 1, IF( AND(E8=2, SUM(F8, G8)>1), 1, 0 ) ) -> 0 | N8: =IF(B8/C8 > 0.8, 1, IF( AND(E8=2, SUM(F8, G8)>3), 1, 0 ) ) -> 0 | O8: =IF(B8/C8 > 0.9, 1, 0) -> 0 | P8: =ROUNDDOWN(B8/C8,0) -> 0 | U8: 0 | V8: 0 | W8: 1 | X8: 0 | Y8: 0 | Z8: 1 | AA8: 0 | AB8: 0
B9: =(SUM(U9:AB9)) -> 3 | C9: =(COUNT(U9:AB9)) -> 8 | D9: =ROUNDUP( MAX( IF(P9,100, IF(O9,80, IF(N9,70, IF(M9,60, IF(L9,55, IF(K9,50, IF(J9,45, IF(I9,35, IF(H9,25, 0))))))))), 100 * B9/C9 ) * 10 / 100,0) -> 6 | E9: =SUM(U9, Z9) -> 2 | F9: =SUM(V9, W9, X9) -> 1 | G9: =SUM(Y9, AA9, AB9) -> 0 | H9: =IF(B9>0,1,0) -> 1 | I9: =IF( B9/C9 > 0.2, 1, IF(E9>0, 1, 0) ) -> 1 | J9: =IF( B9/C9 > 0.4, 1, IF( E9=2, 1, IF(AND(E9>0, OR(F9>0, G9>0)), 1, 0 ) )) -> 1 | K9: =IF(B9/C9 > 0.5, 1, IF( E9=2, 1, IF(AND(E9>0, OR(F9>1, G9>0)), 1, 0 ) )) -> 1 | L9: =IF(B9/C9 > 0.6, 1, IF( AND(E9=2, OR(F9>0, G9>0)), 1, 0 ) ) -> 1 | M9: =IF(B9/C9 > 0.7, 1, IF( AND(E9=2, SUM(F9, G9)>1), 1, 0 ) ) -> 0 | N9: =IF(B9/C9 > 0.8, 1, IF( AND(E9=2, SUM(F9, G9)>3), 1, 0 ) ) -> 0 | O9: =IF(B9/C9 > 0.9, 1, 0) -> 0 | P9: =ROUNDDOWN(B9/C9,0) -> 0 | U9: 1 | V9: 0 | W9: 1 | X9: 0 | Y9: 0 | Z9: 1 | AA9: 0 | AB9: 0
B10: =(SUM(U10:AB10)) -> 2 | C10: =(COUNT(U10:AB10)) -> 8 | D10: =ROUNDUP( MAX( IF(P10,100, IF(O10,80, IF(N10,70, IF(M10,60, IF(L10,55, IF(K10,50, IF(J10,45, IF(I10,35, IF(H10,25, 0))))))))), 100 * B10/C10 ) * 10 / 100,0) -> 5 | E10: =SUM(U10, Z10) -> 2 | F10: =SUM(V10, W10, X10) -> 0 | G10: =SUM(Y10, AA10, AB10) -> 0 | H10: =IF(B10>0,1,0) -> 1 | I10: =IF( B10/C10 > 0.2, 1, IF(E10>0, 1, 0) ) -> 1 | J10: =IF( B10/C10 > 0.4, 1, IF( E10=2, 1, IF(AND(E10>0, OR(F10>0, G10>0)), 1, 0 ) )) -> 1 | K10: =IF(B10/C10 > 0.5, 1, IF( E10=2, 1, IF(AND(E10>0, OR(F10>1, G10>0)), 1, 0 ) )) -> 1 | L10: =IF(B10/C10 > 0.6, 1, IF( AND(E10=2, OR(F10>0, G10>0)), 1, 0 ) ) -> 0 | M10: =IF(B10/C10 > 0.7, 1, IF( AND(E10=2, SUM(F10, G10)>1), 1, 0 ) ) -> 0 | N10: =IF(B10/C10 > 0.8, 1, IF( AND(E10=2, SUM(F10, G10)>3), 1, 0 ) ) -> 0 | O10: =IF(B10/C10 > 0.9, 1, 0) -> 0 | P10: =ROUNDDOWN(B10/C10,0) -> 0 | U10: 1 | V10: 0 | W10: 0 | X10: 0 | Y10: 0 | Z10: 1 | AA10: 0 | AB10: 0
B11: =(SUM(U11:AB11)) -> 3 | C11: =(COUNT(U11:AB11)) -> 8 | D11: =ROUNDUP( MAX( IF(P11,100, IF(O11,80, IF(N11,70, IF(M11,60, IF(L11,55, IF(K11,50, IF(J11,45, IF(I11,35, IF(H11,25, 0))))))))), 100 * B11/C11 ) * 10 / 100,0) -> 6 | E11: =SUM(U11, Z11) -> 2 | F11: =SUM(V11, W11, X11) -> 1 | G11: =SUM(Y11, AA11, AB11) -> 0 | H11: =IF(B11>0,1,0) -> 1 | I11: =IF( B11/C11 > 0.2, 1, IF(E11>0, 1, 0) ) -> 1 | J11: =IF( B11/C11 > 0.4, 1, IF( E11=2, 1, IF(AND(E11>0, OR(F11>0, G11>0)), 1, 0 ) )) -> 1 | K11: =IF(B11/C11 > 0.5, 1, IF( E11=2, 1, IF(AND(E11>0, OR(F11>1, G11>0)), 1, 0 ) )) -> 1 | L11: =IF(B11/C11 > 0.6, 1, IF( AND(E11=2, OR(F11>0, G11>0)), 1, 0 ) ) -> 1 | M11: =IF(B11/C11 > 0.7, 1, IF( AND(E11=2, SUM(F11, G11)>1), 1, 0 ) ) -> 0 | N11: =IF(B11/C11 > 0.8, 1, IF( AND(E11=2, SUM(F11, G11)>3), 1, 0 ) ) -> 0 | O11: =IF(B11/C11 > 0.9, 1, 0) -> 0 | P11: =ROUNDDOWN(B11/C11,0) -> 0 | U11: 1 | V11: 0 | W11: 1 | X11: 0 | Y11: 0 | Z11: 1 | AA11: 0 | AB11: 0
B12: =(SUM(U12:AB12)) -> 5 | C12: =(COUNT(U12:AB12)) -> 8 | D12: =ROUNDUP( MAX( IF(P12,100, IF(O12,80, IF(N12,70, IF(M12,60, IF(L12,55, IF(K12,50, IF(J12,45, IF(I12,35, IF(H12,25, 0))))))))), 100 * B12/C12 ) * 10 / 100,0) -> 7 | E12: =SUM(U12, Z12) -> 2 | F12: =SUM(V12, W12, X12) -> 3 | G12: =SUM(Y12, AA12, AB12) -> 0 | H12: =IF(B12>0,1,0) -> 1 | I12: =IF( B12/C12 > 0.2, 1, IF(E12>0, 1, 0) ) -> 1 | J12: =IF( B12/C12 > 0.4, 1, IF( E12=2, 1, IF(AND(E12>0, OR(F12>0, G12>0)), 1, 0 ) )) -> 1 | K12: =IF(B12/C12 > 0.5, 1, IF( E12=2, 1, IF(AND(E12>0, OR(F12>1, G12>0)), 1, 0 ) )) -> 1 | L12: =IF(B12/C12 > 0.6, 1, IF( AND(E12=2, OR(F12>0, G12>0)), 1, 0 ) ) -> 1 | M12: =IF(B12/C12 > 0.7, 1, IF( AND(E12=2, SUM(F12, G12)>1), 1, 0 ) ) -> 1 | N12: =IF(B12/C12 > 0.8, 1, IF( AND(E12=2, SUM(F12, G12)>3), 1, 0 ) ) -> 0 | O12: =IF(B12/C12 > 0.9, 1, 0) -> 0 | P12: =ROUNDDOWN(B12/C12,0) -> 0 | U12: 1 | V12: 1 | W12: 1 | X12: 1 | Y12: 0 | Z12: 1 | AA12: 0 | AB12: 0
B13: =(SUM(U13:AB13)) -> 5 | C13: =(COUNT(U13:AB13)) -> 8 | D13: =ROUNDUP( MAX( IF(P13,100, IF(O13,80, IF(N13,70, IF(M13,60, IF(L13,55, IF(K13,50, IF(J13,45, IF(I13,35, IF(H13,25, 0))))))))), 100 * B13/C13 ) * 10 / 100,0) -> 7 | E13: =SUM(U13, Z13) -> 2 | F13: =SUM(V13, W13, X13) -> 3 | G13: =SUM(Y13, AA13, AB13) -> 0 | H13: =IF(B13>0,1,0) -> 1 | I13: =IF( B13/C13 > 0.2, 1, IF(E13>0, 1, 0) ) -> 1 | J13: =IF( B13/C13 > 0.4, 1, IF( E13=2, 1, IF(AND(E13>0, OR(F13>0, G13>0)), 1, 0 ) )) -> 1 | K13: =IF(B13/C13 > 0.5, 1, IF( E13=2, 1, IF(AND(E13>0, OR(F13>1, G13>0)), 1, 0 ) )) -> 1 | L13: =IF(B13/C13 > 0.6, 1, IF( AND(E13=2, OR(F13>0, G13>0)), 1, 0 ) ) -> 1 | M13: =IF(B13/C13 > 0.7, 1, IF( AND(E13=2, SUM(F13, G13)>1), 1, 0 ) ) -> 1 | N13: =IF(B13/C13 > 0.8, 1, IF( AND(E13=2, SUM(F13, G13)>3), 1, 0 ) ) -> 0 | O13: =IF(B13/C13 > 0.9, 1, 0) -> 0 | P13: =ROUNDDOWN(B13/C13,0) -> 0 | U13: 1 | V13: 1 | W13: 1 | X13: 1 | Y13: 0 | Z13: 1 | AA13: 0 | AB13: 0
B14: =(SUM(U14:AB14)) -> 2 | C14: =(COUNT(U14:AB14)) -> 8 | D14: =ROUNDUP( MAX( IF(P14,100, IF(O14,80, IF(N14,70, IF(M14,60, IF(L14,55, IF(K14,50, IF(J14,45, IF(I14,35, IF(H14,25, 0))))))))), 100 * B14/C14 ) * 10 / 100,0) -> 5 | E14: =SUM(U14, Z14) -> 2 | F14: =SUM(V14, W14, X14) -> 0 | G14: =SUM(Y14, AA14, AB14) -> 0 | H14: =IF(B14>0,1,0) -> 1 | I14: =IF( B14/C14 > 0.2, 1, IF(E14>0, 1, 0) ) -> 1 | J14: =IF( B14/C14 > 0.4, 1, IF( E14=2, 1, IF(AND(E14>0, OR(F14>0, G14>0)), 1, 0 ) )) -> 1 | K14: =IF(B14/C14 > 0.5, 1, IF( E14=2, 1, IF(AND(E14>0, OR(F14>1, G14>0)), 1, 0 ) )) -> 1 | L14: =IF(B14/C14 > 0.6, 1, IF( AND(E14=2, OR(F14>0, G14>0)), 1, 0 ) ) -> 0 | M14: =IF(B14/C14 > 0.7, 1, IF( AND(E14=2, SUM(F14, G14)>1), 1, 0 ) ) -> 0 | N14: =IF(B14/C14 > 0.8, 1, IF( AND(E14=2, SUM(F14, G14)>3), 1, 0 ) ) -> 0 | O14: =IF(B14/C14 > 0.9, 1, 0) -> 0 | P14: =ROUNDDOWN(B14/C14,0) -> 0 | U14: 1 | V14: 0 | W14: 0 | X14: 0 | Y14: 0 | Z14: 1 | AA14: 0 | AB14: 0
B15: =(SUM(U15:AB15)) -> 2 | C15: =(COUNT(U15:AB15)) -> 8 | D15: =ROUNDUP( MAX( IF(P15,100, IF(O15,80, IF(N15,70, IF(M15,60, IF(L15,55, IF(K15,50, IF(J15,45, IF(I15,35, IF(H15,25, 0))))))))), 100 * B15/C15 ) * 10 / 100,0) -> 5 | E15: =SUM(U15, Z15) -> 2 | F15: =SUM(V15, W15, X15) -> 0 | G15: =SUM(Y15, AA15, AB15) -> 0 | H15: =IF(B15>0,1,0) -> 1 | I15: =IF( B15/C15 > 0.2, 1, IF(E15>0, 1, 0) ) -> 1 | J15: =IF( B15/C15 > 0.4, 1, IF( E15=2, 1, IF(AND(E15>0, OR(F15>0, G15>0)), 1, 0 ) )) -> 1 | K15: =IF(B15/C15 > 0.5, 1, IF( E15=2, 1, IF(AND(E15>0, OR(F15>1, G15>0)), 1, 0 ) )) -> 1 | L15: =IF(B15/C15 > 0.6, 1, IF( AND(E15=2, OR(F15>0, G15>0)), 1, 0 ) ) -> 0 | M15: =IF(B15/C15 > 0.7, 1, IF( AND(E15=2, SUM(F15, G15)>1), 1, 0 ) ) -> 0 | N15: =IF(B15/C15 > 0.8, 1, IF( AND(E15=2, SUM(F15, G15)>3), 1, 0 ) ) -> 0 | O15: =IF(B15/C15 > 0.9, 1, 0) -> 0 | P15: =ROUNDDOWN(B15/C15,0) -> 0 | U15: 1 | V15: 0 | W15: 0 | X15: 0 | Y15: 0 | Z15: 1 | AA15: 0 | AB15: 0
B16: =(SUM(U16:AB16)) -> 3 | C16: =(COUNT(U16:AB16)) -> 8 | D16: =ROUNDUP( MAX( IF(P16,100, IF(O16,80, IF(N16,70, IF(M16,60, IF(L16,55, IF(K16,50, IF(J16,45, IF(I16,35, IF(H16,25, 0))))))))), 100 * B16/C16 ) * 10 / 100,0) -> 6 | E16: =SUM(U16, Z16) -> 2 | F16: =SUM(V16, W16, X16) -> 1 | G16: =SUM(Y16, AA16, AB16) -> 0 | H16: =IF(B16>0,1,0) -> 1 | I16: =IF( B16/C16 > 0.2, 1, IF(E16>0, 1, 0) ) -> 1 | J16: =IF( B16/C16 > 0.4, 1, IF( E16=2, 1, IF(AND(E16>0, OR(F16>0, G16>0)), 1, 0 ) )) -> 1 | K16: =IF(B16/C16 > 0.5, 1, IF( E16=2, 1, IF(AND(E16>0, OR(F16>1, G16>0)), 1, 0 ) )) -> 1 | L16: =IF(B16/C16 > 0.6, 1, IF( AND(E16=2, OR(F16>0, G16>0)), 1, 0 ) ) -> 1 | M16: =IF(B16/C16 > 0.7, 1, IF( AND(E16=2, SUM(F16, G16)>1), 1, 0 ) ) -> 0 | N16: =IF(B16/C16 > 0.8, 1, IF( AND(E16=2, SUM(F16, G16)>3), 1, 0 ) ) -> 0 | O16: =IF(B16/C16 > 0.9, 1, 0) -> 0 | P16: =ROUNDDOWN(B16/C16,0) -> 0 | U16: 1 | V16: 1 | W16: 0 | X16: 0 | Y16: 0 | Z16: 1 | AA16: 0 | AB16: 0
B17: =(SUM(U17:AB17)) -> 2 | C17: =(COUNT(U17:AB17)) -> 8 | D17: =ROUNDUP( MAX( IF(P17,100, IF(O17,80, IF(N17,70, IF(M17,60, IF(L17,55, IF(K17,50, IF(J17,45, IF(I17,35, IF(H17,25, 0))))))))), 100 * B17/C17 ) * 10 / 100,0) -> 5 | E17: =SUM(U17, Z17) -> 2 | F17: =SUM(V17, W17, X17) -> 0 | G17: =SUM(Y17, AA17, AB17) -> 0 | H17: =IF(B17>0,1,0) -> 1 | I17: =IF( B17/C17 > 0.2, 1, IF(E17>0, 1, 0) ) -> 1 | J17: =IF( B17/C17 > 0.4, 1, IF( E17=2, 1, IF(AND(E17>0, OR(F17>0, G17>0)), 1, 0 ) )) -> 1 | K17: =IF(B17/C17 > 0.5, 1, IF( E17=2, 1, IF(AND(E17>0, OR(F17>1, G17>0)), 1, 0 ) )) -> 1 | L17: =IF(B17/C17 > 0.6, 1, IF( AND(E17=2, OR(F17>0, G17>0)), 1, 0 ) ) -> 0 | M17: =IF(B17/C17 > 0.7, 1, IF( AND(E17=2, SUM(F17, G17)>1), 1, 0 ) ) -> 0 | N17: =IF(B17/C17 > 0.8, 1, IF( AND(E17=2, SUM(F17, G17)>3), 1, 0 ) ) -> 0 | O17: =IF(B17/C17 > 0.9, 1, 0) -> 0 | P17: =ROUNDDOWN(B17/C17,0) -> 0 | U17: 1 | V17: 0 | W17: 0 | X17: 0 | Y17: 0 | Z17: 1 | AA17: 0 | AB17: 0
B18: =(SUM(U18:AB18)) -> 5 | C18: =(COUNT(U18:AB18)) -> 8 | D18: =ROUNDUP( MAX( IF(P18,100, IF(O18,80, IF(N18,70, IF(M18,60, IF(L18,55, IF(K18,50, IF(J18,45, IF(I18,35, IF(H18,25, 0))))))))), 100 * B18/C18 ) * 10 / 100,0) -> 7 | E18: =SUM(U18, Z18) -> 2 | F18: =SUM(V18, W18, X18) -> 3 | G18: =SUM(Y18, AA18, AB18) -> 0 | H18: =IF(B18>0,1,0) -> 1 | I18: =IF( B18/C18 > 0.2, 1, IF(E18>0, 1, 0) ) -> 1 | J18: =IF( B18/C18 > 0.4, 1, IF( E18=2, 1, IF(AND(E18>0, OR(F18>0, G18>0)), 1, 0 ) )) -> 1 | K18: =IF(B18/C18 > 0.5, 1, IF( E18=2, 1, IF(AND(E18>0, OR(F18>1, G18>0)), 1, 0 ) )) -> 1 | L18: =IF(B18/C18 > 0.6, 1, IF( AND(E18=2, OR(F18>0, G18>0)), 1, 0 ) ) -> 1 | M18: =IF(B18/C18 > 0.7, 1, IF( AND(E18=2, SUM(F18, G18)>1), 1, 0 ) ) -> 1 | N18: =IF(B18/C18 > 0.8, 1, IF( AND(E18=2, SUM(F18, G18)>3), 1, 0 ) ) -> 0 | O18: =IF(B18/C18 > 0.9, 1, 0) -> 0 | P18: =ROUNDDOWN(B18/C18,0) -> 0 | U18: 1 | V18: 1 | W18: 1 | X18: 1 | Y18: 0 | Z18: 1 | AA18: 0 | AB18: 0
... B52: =(SUM(U52:AB52)) -> 3 | C52: =(COUNT(U52:AB52)) -> 8 | D52: =ROUNDUP( MAX( IF(P52,100, IF(O52,80, IF(N52,70, IF(M52,60, IF(L52,55, IF(K52,50, IF(J52,45, IF(I52,35, IF(H52,25, 0))))))))), 100 * B52/C52 ) * 10 / 100,0) -> 5 | E52: =SUM(U52, Z52) -> 1 | F52: =SUM(V52, W52, X52) -> 2 | G52: =SUM(Y52, AA52, AB52) -> 0 | H52: =IF(B52>0,1,0) -> 1 | I52: =IF( B52/C52 > 0.2, 1, IF(E52>0, 1, 0) ) -> 1 | J52: =IF( B52/C52 > 0.4, 1, IF( E52=2, 1, IF(AND(E52>0, OR(F52>0, G52>0)), 1, 0 ) )) -> 1 | K52: =IF(B52/C52 > 0.5, 1, IF( E52=2, 1, IF(AND(E52>0, OR(F52>1, G52>0)), 1, 0 ) )) -> 1 | L52: =IF(B52/C52 > 0.6, 1, IF( AND(E52=2, OR(F52>0, G52>0)), 1, 0 ) ) -> 0 | M52: =IF(B52/C52 > 0.7, 1, IF( AND(E52=2, SUM(F52, G52)>1), 1, 0 ) ) -> 0 | N52: =IF(B52/C52 > 0.8, 1, IF( AND(E52=2, SUM(F52, G52)>3), 1, 0 ) ) -> 0 | O52: =IF(B52/C52 > 0.9, 1, 0) -> 0 | P52: =ROUNDDOWN(B52/C52,0) -> 0 | U52: 0 | V52: 0 | W52: 1 | X52: 1 | Y52: 0 | Z52: 1 | AA52: 0 | AB52: 0
B53: =(SUM(U53:AB53)) -> 1 | C53: =(COUNT(U53:AB53)) -> 8 | D53: =ROUNDUP( MAX( IF(P53,100, IF(O53,80, IF(N53,70, IF(M53,60, IF(L53,55, IF(K53,50, IF(J53,45, IF(I53,35, IF(H53,25, 0))))))))), 100 * B53/C53 ) * 10 / 100,0) -> 4 | E53: =SUM(U53, Z53) -> 1 | F53: =SUM(V53, W53, X53) -> 0 | G53: =SUM(Y53, AA53, AB53) -> 0 | H53: =IF(B53>0,1,0) -> 1 | I53: =IF( B53/C53 > 0.2, 1, IF(E53>0, 1, 0) ) -> 1 | J53: =IF( B53/C53 > 0.4, 1, IF( E53=2, 1, IF(AND(E53>0, OR(F53>0, G53>0)), 1, 0 ) )) -> 0 | K53: =IF(B53/C53 > 0.5, 1, IF( E53=2, 1, IF(AND(E53>0, OR(F53>1, G53>0)), 1, 0 ) )) -> 0 | L53: =IF(B53/C53 > 0.6, 1, IF( AND(E53=2, OR(F53>0, G53>0)), 1, 0 ) ) -> 0 | M53: =IF(B53/C53 > 0.7, 1, IF( AND(E53=2, SUM(F53, G53)>1), 1, 0 ) ) -> 0 | N53: =IF(B53/C53 > 0.8, 1, IF( AND(E53=2, SUM(F53, G53)>3), 1, 0 ) ) -> 0 | O53: =IF(B53/C53 > 0.9, 1, 0) -> 0 | P53: =ROUNDDOWN(B53/C53,0) -> 0 | U53: 1 | V53: 0 | W53: 0 | X53: 0 | Y53: 0 | Z53: 0 | AA53: 0 | AB53: 0 | AC53: You start discussing individual benefits. A discussion of their interplay would have ben meaningful. Other than that, this was about the "how".
B54: =(SUM(U54:AB54)) -> 3 | C54: =(COUNT(U54:AB54)) -> 8 | D54: =ROUNDUP( MAX( IF(P54,100, IF(O54,80, IF(N54,70, IF(M54,60, IF(L54,55, IF(K54,50, IF(J54,45, IF(I54,35, IF(H54,25, 0))))))))), 100 * B54/C54 ) * 10 / 100,0) -> 5 | E54: =SUM(U54, Z54) -> 1 | F54: =SUM(V54, W54, X54) -> 1 | G54: =SUM(Y54, AA54, AB54) -> 1 | H54: =IF(B54>0,1,0) -> 1 | I54: =IF( B54/C54 > 0.2, 1, IF(E54>0, 1, 0) ) -> 1 | J54: =IF( B54/C54 > 0.4, 1, IF( E54=2, 1, IF(AND(E54>0, OR(F54>0, G54>0)), 1, 0 ) )) -> 1 | K54: =IF(B54/C54 > 0.5, 1, IF( E54=2, 1, IF(AND(E54>0, OR(F54>1, G54>0)), 1, 0 ) )) -> 1 | L54: =IF(B54/C54 > 0.6, 1, IF( AND(E54=2, OR(F54>0, G54>0)), 1, 0 ) ) -> 0 | M54: =IF(B54/C54 > 0.7, 1, IF( AND(E54=2, SUM(F54, G54)>1), 1, 0 ) ) -> 0 | N54: =IF(B54/C54 > 0.8, 1, IF( AND(E54=2, SUM(F54, G54)>3), 1, 0 ) ) -> 0 | O54: =IF(B54/C54 > 0.9, 1, 0) -> 0 | P54: =ROUNDDOWN(B54/C54,0) -> 0 | U54: 0 | V54: 0 | W54: 1 | X54: 0 | Y54: 1 | Z54: 1 | AA54: 0 | AB54: 0
B55: =(SUM(U55:AB55)) -> 2 | C55: =(COUNT(U55:AB55)) -> 8 | D55: =ROUNDUP( MAX( IF(P55,100, IF(O55,80, IF(N55,70, IF(M55,60, IF(L55,55, IF(K55,50, IF(J55,45, IF(I55,35, IF(H55,25, 0))))))))), 100 * B55/C55 ) * 10 / 100,0) -> 5 | E55: =SUM(U55, Z55) -> 1 | F55: =SUM(V55, W55, X55) -> 1 | G55: =SUM(Y55, AA55, AB55) -> 0 | H55: =IF(B55>0,1,0) -> 1 | I55: =IF( B55/C55 > 0.2, 1, IF(E55>0, 1, 0) ) -> 1 | J55: =IF( B55/C55 > 0.4, 1, IF( E55=2, 1, IF(AND(E55>0, OR(F55>0, G55>0)), 1, 0 ) )) -> 1 | K55: =IF(B55/C55 > 0.5, 1, IF( E55=2, 1, IF(AND(E55>0, OR(F55>1, G55>0)), 1, 0 ) )) -> 0 | L55: =IF(B55/C55 > 0.6, 1, IF( AND(E55=2, OR(F55>0, G55>0)), 1, 0 ) ) -> 0 | M55: =IF(B55/C55 > 0.7, 1, IF( AND(E55=2, SUM(F55, G55)>1), 1, 0 ) ) -> 0 | N55: =IF(B55/C55 > 0.8, 1, IF( AND(E55=2, SUM(F55, G55)>3), 1, 0 ) ) -> 0 | O55: =IF(B55/C55 > 0.9, 1, 0) -> 0 | P55: =ROUNDDOWN(B55/C55,0) -> 0 | U55: 0 | V55: 1 | W55: 0 | X55: 0 | Y55: 0 | Z55: 1 | AA55: 0 | AB55: 0
B56: =(SUM(U56:AB56)) -> 3 | C56: =(COUNT(U56:AB56)) -> 8 | D56: =ROUNDUP( MAX( IF(P56,100, IF(O56,80, IF(N56,70, IF(M56,60, IF(L56,55, IF(K56,50, IF(J56,45, IF(I56,35, IF(H56,25, 0))))))))), 100 * B56/C56 ) * 10 / 100,0) -> 6 | E56: =SUM(U56, Z56) -> 2 | F56: =SUM(V56, W56, X56) -> 1 | G56: =SUM(Y56, AA56, AB56) -> 0 | H56: =IF(B56>0,1,0) -> 1 | I56: =IF( B56/C56 > 0.2, 1, IF(E56>0, 1, 0) ) -> 1 | J56: =IF( B56/C56 > 0.4, 1, IF( E56=2, 1, IF(AND(E56>0, OR(F56>0, G56>0)), 1, 0 ) )) -> 1 | K56: =IF(B56/C56 > 0.5, 1, IF( E56=2, 1, IF(AND(E56>0, OR(F56>1, G56>0)), 1, 0 ) )) -> 1 | L56: =IF(B56/C56 > 0.6, 1, IF( AND(E56=2, OR(F56>0, G56>0)), 1, 0 ) ) -> 1 | M56: =IF(B56/C56 > 0.7, 1, IF( AND(E56=2, SUM(F56, G56)>1), 1, 0 ) ) -> 0 | N56: =IF(B56/C56 > 0.8, 1, IF( AND(E56=2, SUM(F56, G56)>3), 1, 0 ) ) -> 0 | O56: =IF(B56/C56 > 0.9, 1, 0) -> 0 | P56: =ROUNDDOWN(B56/C56,0) -> 0 | U56: 1 | V56: 1 | W56: 0 | X56: 0 | Y56: 0 | Z56: 1 | AA56: 0 | AB56: 0
B57: =(SUM(U57:AB57)) -> 2 | C57: =(COUNT(U57:AB57)) -> 8 | D57: =ROUNDUP( MAX( IF(P57,100, IF(O57,80, IF(N57,70, IF(M57,60, IF(L57,55, IF(K57,50, IF(J57,45, IF(I57,35, IF(H57,25, 0))))))))), 100 * B57/C57 ) * 10 / 100,0) -> 5 | E57: =SUM(U57, Z57) -> 1 | F57: =SUM(V57, W57, X57) -> 1 | G57: =SUM(Y57, AA57, AB57) -> 0 | H57: =IF(B57>0,1,0) -> 1 | I57: =IF( B57/C57 > 0.2, 1, IF(E57>0, 1, 0) ) -> 1 | J57: =IF( B57/C57 > 0.4, 1, IF( E57=2, 1, IF(AND(E57>0, OR(F57>0, G57>0)), 1, 0 ) )) -> 1 | K57: =IF(B57/C57 > 0.5, 1, IF( E57=2, 1, IF(AND(E57>0, OR(F57>1, G57>0)), 1, 0 ) )) -> 0 | L57: =IF(B57/C57 > 0.6, 1, IF( AND(E57=2, OR(F57>0, G57>0)), 1, 0 ) ) -> 0 | M57: =IF(B57/C57 > 0.7, 1, IF( AND(E57=2, SUM(F57, G57)>1), 1, 0 ) ) -> 0 | N57: =IF(B57/C57 > 0.8, 1, IF( AND(E57=2, SUM(F57, G57)>3), 1, 0 ) ) -> 0 | O57: =IF(B57/C57 > 0.9, 1, 0) -> 0 | P57: =ROUNDDOWN(B57/C57,0) -> 0 | U57: 0 | V57: 0 | W57: 1 | X57: 0 | Y57: 0 | Z57: 1 | AA57: 0 | AB57: 0
B58: =(SUM(U58:AB58)) -> 5 | C58: =(COUNT(U58:AB58)) -> 8 | D58: =ROUNDUP( MAX( IF(P58,100, IF(O58,80, IF(N58,70, IF(M58,60, IF(L58,55, IF(K58,50, IF(J58,45, IF(I58,35, IF(H58,25, 0))))))))), 100 * B58/C58 ) * 10 / 100,0) -> 7 | E58: =SUM(U58, Z58) -> 2 | F58: =SUM(V58, W58, X58) -> 2 | G58: =SUM(Y58, AA58, AB58) -> 1 | H58: =IF(B58>0,1,0) -> 1 | I58: =IF( B58/C58 > 0.2, 1, IF(E58>0, 1, 0) ) -> 1 | J58: =IF( B58/C58 > 0.4, 1, IF( E58=2, 1, IF(AND(E58>0, OR(F58>0, G58>0)), 1, 0 ) )) -> 1 | K58: =IF(B58/C58 > 0.5, 1, IF( E58=2, 1, IF(AND(E58>0, OR(F58>1, G58>0)), 1, 0 ) )) -> 1 | L58: =IF(B58/C58 > 0.6, 1, IF( AND(E58=2, OR(F58>0, G58>0)), 1, 0 ) ) -> 1 | M58: =IF(B58/C58 > 0.7, 1, IF( AND(E58=2, SUM(F58, G58)>1), 1, 0 ) ) -> 1 | N58: =IF(B58/C58 > 0.8, 1, IF( AND(E58=2, SUM(F58, G58)>3), 1, 0 ) ) -> 0 | O58: =IF(B58/C58 > 0.9, 1, 0) -> 0 | P58: =ROUNDDOWN(B58/C58,0) -> 0 | U58: 1 | V58: 1 | W58: 1 | X58: 0 | Y58: 1 | Z58: 1 | AA58: 0 | AB58: 0
B59: =(SUM(U59:AB59)) -> 3 | C59: =(COUNT(U59:AB59)) -> 8 | D59: =ROUNDUP( MAX( IF(P59,100, IF(O59,80, IF(N59,70, IF(M59,60, IF(L59,55, IF(K59,50, IF(J59,45, IF(I59,35, IF(H59,25, 0))))))))), 100 * B59/C59 ) * 10 / 100,0) -> 5 | E59: =SUM(U59, Z59) -> 1 | F59: =SUM(V59, W59, X59) -> 2 | G59: =SUM(Y59, AA59, AB59) -> 0 | H59: =IF(B59>0,1,0) -> 1 | I59: =IF( B59/C59 > 0.2, 1, IF(E59>0, 1, 0) ) -> 1 | J59: =IF( B59/C59 > 0.4, 1, IF( E59=2, 1, IF(AND(E59>0, OR(F59>0, G59>0)), 1, 0 ) )) -> 1 | K59: =IF(B59/C59 > 0.5, 1, IF( E59=2, 1, IF(AND(E59>0, OR(F59>1, G59>0)), 1, 0 ) )) -> 1 | L59: =IF(B59/C59 > 0.6, 1, IF( AND(E59=2, OR(F59>0, G59>0)), 1, 0 ) ) -> 0 | M59: =IF(B59/C59 > 0.7, 1, IF( AND(E59=2, SUM(F59, G59)>1), 1, 0 ) ) -> 0 | N59: =IF(B59/C59 > 0.8, 1, IF( AND(E59=2, SUM(F59, G59)>3), 1, 0 ) ) -> 0 | O59: =IF(B59/C59 > 0.9, 1, 0) -> 0 | P59: =ROUNDDOWN(B59/C59,0) -> 0 | U59: 0 | V59: 1 | W59: 1 | X59: 0 | Y59: 0 | Z59: 1 | AA59: 0 | AB59: 0
B60: =(SUM(U60:AB60)) -> 4 | C60: =(COUNT(U60:AB60)) -> 8 | D60: =ROUNDUP( MAX( IF(P60,100, IF(O60,80, IF(N60,70, IF(M60,60, IF(L60,55, IF(K60,50, IF(J60,45, IF(I60,35, IF(H60,25, 0))))))))), 100 * B60/C60 ) * 10 / 100,0) -> 5 | E60: =SUM(U60, Z60) -> 1 | F60: =SUM(V60, W60, X60) -> 3 | G60: =SUM(Y60, AA60, AB60) -> 0 | H60: =IF(B60>0,1,0) -> 1 | I60: =IF( B60/C60 > 0.2, 1, IF(E60>0, 1, 0) ) -> 1 | J60: =IF( B60/C60 > 0.4, 1, IF( E60=2, 1, IF(AND(E60>0, OR(F60>0, G60>0)), 1, 0 ) )) -> 1 | K60: =IF(B60/C60 > 0.5, 1, IF( E60=2, 1, IF(AND(E60>0, OR(F60>1, G60>0)), 1, 0 ) )) -> 1 | L60: =IF(B60/C60 > 0.6, 1, IF( AND(E60=2, OR(F60>0, G60>0)), 1, 0 ) ) -> 0 | M60: =IF(B60/C60 > 0.7, 1, IF( AND(E60=2, SUM(F60, G60)>1), 1, 0 ) ) -> 0 | N60: =IF(B60/C60 > 0.8, 1, IF( AND(E60=2, SUM(F60, G60)>3), 1, 0 ) ) -> 0 | O60: =IF(B60/C60 > 0.9, 1, 0) -> 0 | P60: =ROUNDDOWN(B60/C60,0) -> 0 | U60: 0 | V60: 1 | W60: 1 | X60: 1 | Y60: 0 | Z60: 1 | AA60: 0 | AB60: 0
B61: =(SUM(U61:AB61)) -> 2 | C61: =(COUNT(U61:AB61)) -> 8 | D61: =ROUNDUP( MAX( IF(P61,100, IF(O61,80, IF(N61,70, IF(M61,60, IF(L61,55, IF(K61,50, IF(J61,45, IF(I61,35, IF(H61,25, 0))))))))), 100 * B61/C61 ) * 10 / 100,0) -> 5 | E61: =SUM(U61, Z61) -> 1 | F61: =SUM(V61, W61, X61) -> 0 | G61: =SUM(Y61, AA61, AB61) -> 1 | H61: =IF(B61>0,1,0) -> 1 | I61: =IF( B61/C61 > 0.2, 1, IF(E61>0, 1, 0) ) -> 1 | J61: =IF( B61/C61 > 0.4, 1, IF( E61=2, 1, IF(AND(E61>0, OR(F61>0, G61>0)), 1, 0 ) )) -> 1 | K61: =IF(B61/C61 > 0.5, 1, IF( E61=2, 1, IF(AND(E61>0, OR(F61>1, G61>0)), 1, 0 ) )) -> 1 | L61: =IF(B61/C61 > 0.6, 1, IF( AND(E61=2, OR(F61>0, G61>0)), 1, 0 ) ) -> 0 | M61: =IF(B61/C61 > 0.7, 1, IF( AND(E61=2, SUM(F61, G61)>1), 1, 0 ) ) -> 0 | N61: =IF(B61/C61 > 0.8, 1, IF( AND(E61=2, SUM(F61, G61)>3), 1, 0 ) ) -> 0 | O61: =IF(B61/C61 > 0.9, 1, 0) -> 0 | P61: =ROUNDDOWN(B61/C61,0) -> 0 | U61: 0 | V61: 0 | W61: 0 | X61: 0 | Y61: 0 | Z61: 1 | AA61: 0 | AB61: 1 | AC61: Good point on the complementarity of the two approaches. Other than that, the questions is about the "how". What they are was covered earlier in the text.
B62: =(SUM(U62:AB62)) -> 1 | C62: =(COUNT(U62:AB62)) -> 8 | D62: =ROUNDUP( MAX( IF(P62,100, IF(O62,80, IF(N62,70, IF(M62,60, IF(L62,55, IF(K62,50, IF(J62,45, IF(I62,35, IF(H62,25, 0))))))))), 100 * B62/C62 ) * 10 / 100,0) -> 4 | E62: =SUM(U62, Z62) -> 1 | F62: =SUM(V62, W62, X62) -> 0 | G62: =SUM(Y62, AA62, AB62) -> 0 | H62: =IF(B62>0,1,0) -> 1 | I62: =IF( B62/C62 > 0.2, 1, IF(E62>0, 1, 0) ) -> 1 | J62: =IF( B62/C62 > 0.4, 1, IF( E62=2, 1, IF(AND(E62>0, OR(F62>0, G62>0)), 1, 0 ) )) -> 0 | K62: =IF(B62/C62 > 0.5, 1, IF( E62=2, 1, IF(AND(E62>0, OR(F62>1, G62>0)), 1, 0 ) )) -> 0 | L62: =IF(B62/C62 > 0.6, 1, IF( AND(E62=2, OR(F62>0, G62>0)), 1, 0 ) ) -> 0 | M62: =IF(B62/C62 > 0.7, 1, IF( AND(E62=2, SUM(F62, G62)>1), 1, 0 ) ) -> 0 | N62: =IF(B62/C62 > 0.8, 1, IF( AND(E62=2, SUM(F62, G62)>3), 1, 0 ) ) -> 0 | O62: =IF(B62/C62 > 0.9, 1, 0) -> 0 | P62: =ROUNDDOWN(B62/C62,0) -> 0 | U62: 0 | V62: 0 | W62: 0 | X62: 0 | Y62: 0 | Z62: 1 | AA62: 0 | AB62: 0
B63: =(SUM(U63:AB63)) -> 2 | C63: =(COUNT(U63:AB63)) -> 8 | D63: =ROUNDUP( MAX( IF(P63,100, IF(O63,80, IF(N63,70, IF(M63,60, IF(L63,55, IF(K63,50, IF(J63,45, IF(I63,35, IF(H63,25, 0))))))))), 100 * B63/C63 ) * 10 / 100,0) -> 5 | E63: =SUM(U63, Z63) -> 2 | F63: =SUM(V63, W63, X63) -> 0 | G63: =SUM(Y63, AA63, AB63) -> 0 | H63: =IF(B63>0,1,0) -> 1 | I63: =IF( B63/C63 > 0.2, 1, IF(E63>0, 1, 0) ) -> 1 | J63: =IF( B63/C63 > 0.4, 1, IF( E63=2, 1, IF(AND(E63>0, OR(F63>0, G63>0)), 1, 0 ) )) -> 1 | K63: =IF(B63/C63 > 0.5, 1, IF( E63=2, 1, IF(AND(E63>0, OR(F63>1, G63>0)), 1, 0 ) )) -> 1 | L63: =IF(B63/C63 > 0.6, 1, IF( AND(E63=2, OR(F63>0, G63>0)), 1, 0 ) ) -> 0 | M63: =IF(B63/C63 > 0.7, 1, IF( AND(E63=2, SUM(F63, G63)>1), 1, 0 ) ) -> 0 | N63: =IF(B63/C63 > 0.8, 1, IF( AND(E63=2, SUM(F63, G63)>3), 1, 0 ) ) -> 0 | O63: =IF(B63/C63 > 0.9, 1, 0) -> 0 | P63: =ROUNDDOWN(B63/C63,0) -> 0 | U63: 1 | V63: 0 | W63: 0 | X63: 0 | Y63: 0 | Z63: 1 | AA63: 0 | AB63: 0
B64: =(SUM(U64:AB64)) -> 4 | C64: =(COUNT(U64:AB64)) -> 8 | D64: =ROUNDUP( MAX( IF(P64,100, IF(O64,80, IF(N64,70, IF(M64,60, IF(L64,55, IF(K64,50, IF(J64,45, IF(I64,35, IF(H64,25, 0))))))))), 100 * B64/C64 ) * 10 / 100,0) -> 6 | E64: =SUM(U64, Z64) -> 2 | F64: =SUM(V64, W64, X64) -> 1 | G64: =SUM(Y64, AA64, AB64) -> 1 | H64: =IF(B64>0,1,0) -> 1 | I64: =IF( B64/C64 > 0.2, 1, IF(E64>0, 1, 0) ) -> 1 | J64: =IF( B64/C64 > 0.4, 1, IF( E64=2, 1, IF(AND(E64>0, OR(F64>0, G64>0)), 1, 0 ) )) -> 1 | K64: =IF(B64/C64 > 0.5, 1, IF( E64=2, 1, IF(AND(E64>0, OR(F64>1, G64>0)), 1, 0 ) )) -> 1 | L64: =IF(B64/C64 > 0.6, 1, IF( AND(E64=2, OR(F64>0, G64>0)), 1, 0 ) ) -> 1 | M64: =IF(B64/C64 > 0.7, 1, IF( AND(E64=2, SUM(F64, G64)>1), 1, 0 ) ) -> 1 | N64: =IF(B64/C64 > 0.8, 1, IF( AND(E64=2, SUM(F64, G64)>3), 1, 0 ) ) -> 0 | O64: =IF(B64/C64 > 0.9, 1, 0) -> 0 | P64: =ROUNDDOWN(B64/C64,0) -> 0 | U64: 1 | V64: 0 | W64: 1 | X64: 0 | Y64: 1 | Z64: 1 | AA64: 0 | AB64: 0
B65: =(SUM(U65:AB65)) -> 3 | C65: =(COUNT(U65:AB65)) -> 8 | D65: =ROUNDUP( MAX( IF(P65,100, IF(O65,80, IF(N65,70, IF(M65,60, IF(L65,55, IF(K65,50, IF(J65,45, IF(I65,35, IF(H65,25, 0))))))))), 100 * B65/C65 ) * 10 / 100,0) -> 5 | E65: =SUM(U65, Z65) -> 1 | F65: =SUM(V65, W65, X65) -> 2 | G65: =SUM(Y65, AA65, AB65) -> 0 | H65: =IF(B65>0,1,0) -> 1 | I65: =IF( B65/C65 > 0.2, 1, IF(E65>0, 1, 0) ) -> 1 | J65: =IF( B65/C65 > 0.4, 1, IF( E65=2, 1, IF(AND(E65>0, OR(F65>0, G65>0)), 1, 0 ) )) -> 1 | K65: =IF(B65/C65 > 0.5, 1, IF( E65=2, 1, IF(AND(E65>0, OR(F65>1, G65>0)), 1, 0 ) )) -> 1 | L65: =IF(B65/C65 > 0.6, 1, IF( AND(E65=2, OR(F65>0, G65>0)), 1, 0 ) ) -> 0 | M65: =IF(B65/C65 > 0.7, 1, IF( AND(E65=2, SUM(F65, G65)>1), 1, 0 ) ) -> 0 | N65: =IF(B65/C65 > 0.8, 1, IF( AND(E65=2, SUM(F65, G65)>3), 1, 0 ) ) -> 0 | O65: =IF(B65/C65 > 0.9, 1, 0) -> 0 | P65: =ROUNDDOWN(B65/C65,0) -> 0 | U65: 0 | V65: 1 | W65: 0 | X65: 1 | Y65: 0 | Z65: 1 | AA65: 0 | AB65: 0
B66: =(SUM(U66:AB66)) -> 2 | C66: =(COUNT(U66:AB66)) -> 8 | D66: =ROUNDUP( MAX( IF(P66,100, IF(O66,80, IF(N66,70, IF(M66,60, IF(L66,55, IF(K66,50, IF(J66,45, IF(I66,35, IF(H66,25, 0))))))))), 100 * B66/C66 ) * 10 / 100,0) -> 5 | E66: =SUM(U66, Z66) -> 2 | F66: =SUM(V66, W66, X66) -> 0 | G66: =SUM(Y66, AA66, AB66) -> 0 | H66: =IF(B66>0,1,0) -> 1 | I66: =IF( B66/C66 > 0.2, 1, IF(E66>0, 1, 0) ) -> 1 | J66: =IF( B66/C66 > 0.4, 1, IF( E66=2, 1, IF(AND(E66>0, OR(F66>0, G66>0)), 1, 0 ) )) -> 1 | K66: =IF(B66/C66 > 0.5, 1, IF( E66=2, 1, IF(AND(E66>0, OR(F66>1, G66>0)), 1, 0 ) )) -> 1 | L66: =IF(B66/C66 > 0.6, 1, IF( AND(E66=2, OR(F66>0, G66>0)), 1, 0 ) ) -> 0 | M66: =IF(B66/C66 > 0.7, 1, IF( AND(E66=2, SUM(F66, G66)>1), 1, 0 ) ) -> 0 | N66: =IF(B66/C66 > 0.8, 1, IF( AND(E66=2, SUM(F66, G66)>3), 1, 0 ) ) -> 0 | O66: =IF(B66/C66 > 0.9, 1, 0) -> 0 | P66: =ROUNDDOWN(B66/C66,0) -> 0 | U66: 1 | V66: 0 | W66: 0 | X66: 0 | Y66: 0 | Z66: 1 | AA66: 0 | AB66: 0
B67: =(SUM(U67:AB67)) -> 5 | C67: =(COUNT(U67:AB67)) -> 8 | D67: =ROUNDUP( MAX( IF(P67,100, IF(O67,80, IF(N67,70, IF(M67,60, IF(L67,55, IF(K67,50, IF(J67,45, IF(I67,35, IF(H67,25, 0))))))))), 100 * B67/C67 ) * 10 / 100,0) -> 7 | E67: =SUM(U67, Z67) -> 2 | F67: =SUM(V67, W67, X67) -> 2 | G67: =SUM(Y67, AA67, AB67) -> 1 | H67: =IF(B67>0,1,0) -> 1 | I67: =IF( B67/C67 > 0.2, 1, IF(E67>0, 1, 0) ) -> 1 | J67: =IF( B67/C67 > 0.4, 1, IF( E67=2, 1, IF(AND(E67>0, OR(F67>0, G67>0)), 1, 0 ) )) -> 1 | K67: =IF(B67/C67 > 0.5, 1, IF( E67=2, 1, IF(AND(E67>0, OR(F67>1, G67>0)), 1, 0 ) )) -> 1 | L67: =IF(B67/C67 > 0.6, 1, IF( AND(E67=2, OR(F67>0, G67>0)), 1, 0 ) ) -> 1 | M67: =IF(B67/C67 > 0.7, 1, IF( AND(E67=2, SUM(F67, G67)>1), 1, 0 ) ) -> 1 | N67: =IF(B67/C67 > 0.8, 1, IF( AND(E67=2, SUM(F67, G67)>3), 1, 0 ) ) -> 0 | O67: =IF(B67/C67 > 0.9, 1, 0) -> 0 | P67: =ROUNDDOWN(B67/C67,0) -> 0 | U67: 1 | V67: 1 | W67: 1 | X67: 0 | Y67: 1 | Z67: 1 | AA67: 0 | AB67: 0
B68: =(SUM(U68:AB68)) -> 3 | C68: =(COUNT(U68:AB68)) -> 8 | D68: =ROUNDUP( MAX( IF(P68,100, IF(O68,80, IF(N68,70, IF(M68,60, IF(L68,55, IF(K68,50, IF(J68,45, IF(I68,35, IF(H68,25, 0))))))))), 100 * B68/C68 ) * 10 / 100,0) -> 6 | E68: =SUM(U68, Z68) -> 2 | F68: =SUM(V68, W68, X68) -> 0 | G68: =SUM(Y68, AA68, AB68) -> 1 | H68: =IF(B68>0,1,0) -> 1 | I68: =IF( B68/C68 > 0.2, 1, IF(E68>0, 1, 0) ) -> 1 | J68: =IF( B68/C68 > 0.4, 1, IF( E68=2, 1, IF(AND(E68>0, OR(F68>0, G68>0)), 1, 0 ) )) -> 1 | K68: =IF(B68/C68 > 0.5, 1, IF( E68=2, 1, IF(AND(E68>0, OR(F68>1, G68>0)), 1, 0 ) )) -> 1 | L68: =IF(B68/C68 > 0.6, 1, IF( AND(E68=2, OR(F68>0, G68>0)), 1, 0 ) ) -> 1 | M68: =IF(B68/C68 > 0.7, 1, IF( AND(E68=2, SUM(F68, G68)>1), 1, 0 ) ) -> 0 | N68: =IF(B68/C68 > 0.8, 1, IF( AND(E68=2, SUM(F68, G68)>3), 1, 0 ) ) -> 0 | O68: =IF(B68/C68 > 0.9, 1, 0) -> 0 | P68: =ROUNDDOWN(B68/C68,0) -> 0 | U68: 1 | V68: 0 | W68: 0 | X68: 0 | Y68: 1 | Z68: 1 | AA68: 0 | AB68: 0
B69: =(SUM(U69:AB69)) -> 3 | C69: =(COUNT(U69:AB69)) -> 8 | D69: =ROUNDUP( MAX( IF(P69,100, IF(O69,80, IF(N69,70, IF(M69,60, IF(L69,55, IF(K69,50, IF(J69,45, IF(I69,35, IF(H69,25, 0))))))))), 100 * B69/C69 ) * 10 / 100,0) -> 6 | E69: =SUM(U69, Z69) -> 2 | F69: =SUM(V69, W69, X69) -> 0 | G69: =SUM(Y69, AA69, AB69) -> 1 | H69: =IF(B69>0,1,0) -> 1 | I69: =IF( B69/C69 > 0.2, 1, IF(E69>0, 1, 0) ) -> 1 | J69: =IF( B69/C69 > 0.4, 1, IF( E69=2, 1, IF(AND(E69>0, OR(F69>0, G69>0)), 1, 0 ) )) -> 1 | K69: =IF(B69/C69 > 0.5, 1, IF( E69=2, 1, IF(AND(E69>0, OR(F69>1, G69>0)), 1, 0 ) )) -> 1 | L69: =IF(B69/C69 > 0.6, 1, IF( AND(E69=2, OR(F69>0, G69>0)), 1, 0 ) ) -> 1 | M69: =IF(B69/C69 > 0.7, 1, IF( AND(E69=2, SUM(F69, G69)>1), 1, 0 ) ) -> 0 | N69: =IF(B69/C69 > 0.8, 1, IF( AND(E69=2, SUM(F69, G69)>3), 1, 0 ) ) -> 0 | O69: =IF(B69/C69 > 0.9, 1, 0) -> 0 | P69: =ROUNDDOWN(B69/C69,0) -> 0 | U69: 1 | V69: 0 | W69: 0 | X69: 0 | Y69: 1 | Z69: 1 | AA69: 0 | AB69: 0
B70: =(SUM(U70:AB70)) -> 3 | C70: =(COUNT(U70:AB70)) -> 8 | D70: =ROUNDUP( MAX( IF(P70,100, IF(O70,80, IF(N70,70, IF(M70,60, IF(L70,55, IF(K70,50, IF(J70,45, IF(I70,35, IF(H70,25, 0))))))))), 100 * B70/C70 ) * 10 / 100,0) -> 6 | E70: =SUM(U70, Z70) -> 2 | F70: =SUM(V70, W70, X70) -> 1 | G70: =SUM(Y70, AA70, AB70) -> 0 | H70: =IF(B70>0,1,0) -> 1 | I70: =IF( B70/C70 > 0.2, 1, IF(E70>0, 1, 0) ) -> 1 | J70: =IF( B70/C70 > 0.4, 1, IF( E70=2, 1, IF(AND(E70>0, OR(F70>0, G70>0)), 1, 0 ) )) -> 1 | K70: =IF(B70/C70 > 0.5, 1, IF( E70=2, 1, IF(AND(E70>0, OR(F70>1, G70>0)), 1, 0 ) )) -> 1 | L70: =IF(B70/C70 > 0.6, 1, IF( AND(E70=2, OR(F70>0, G70>0)), 1, 0 ) ) -> 1 | M70: =IF(B70/C70 > 0.7, 1, IF( AND(E70=2, SUM(F70, G70)>1), 1, 0 ) ) -> 0 | N70: =IF(B70/C70 > 0.8, 1, IF( AND(E70=2, SUM(F70, G70)>3), 1, 0 ) ) -> 0 | O70: =IF(B70/C70 > 0.9, 1, 0) -> 0 | P70: =ROUNDDOWN(B70/C70,0) -> 0 | U70: 1 | V70: 1 | W70: 0 | X70: 0 | Y70: 0 | Z70: 1 | AA70: 0 | AB70: 0
B71: =(SUM(U71:AB71)) -> 6 | C71: =(COUNT(U71:AB71)) -> 8 | D71: =ROUNDUP( MAX( IF(P71,100, IF(O71,80, IF(N71,70, IF(M71,60, IF(L71,55, IF(K71,50, IF(J71,45, IF(I71,35, IF(H71,25, 0))))))))), 100 * B71/C71 ) * 10 / 100,0) -> 8 | E71: =SUM(U71, Z71) -> 2 | F71: =SUM(V71, W71, X71) -> 2 | G71: =SUM(Y71, AA71, AB71) -> 2 | H71: =IF(B71>0,1,0) -> 1 | I71: =IF( B71/C71 > 0.2, 1, IF(E71>0, 1, 0) ) -> 1 | J71: =IF( B71/C71 > 0.4, 1, IF( E71=2, 1, IF(AND(E71>0, OR(F71>0, G71>0)), 1, 0 ) )) -> 1 | K71: =IF(B71/C71 > 0.5, 1, IF( E71=2, 1, IF(AND(E71>0, OR(F71>1, G71>0)), 1, 0 ) )) -> 1 | L71: =IF(B71/C71 > 0.6, 1, IF( AND(E71=2, OR(F71>0, G71>0)), 1, 0 ) ) -> 1 | M71: =IF(B71/C71 > 0.7, 1, IF( AND(E71=2, SUM(F71, G71)>1), 1, 0 ) ) -> 1 | N71: =IF(B71/C71 > 0.8, 1, IF( AND(E71=2, SUM(F71, G71)>3), 1, 0 ) ) -> 1 | O71: =IF(B71/C71 > 0.9, 1, 0) -> 0 | P71: =ROUNDDOWN(B71/C71,0) -> 0 | U71: 1 | V71: 1 | W71: 1 | X71: 0 | Y71: 1 | Z71: 1 | AA71: 1 | AB71: 0
B72: =(SUM(U72:AB72)) -> 5 | C72: =(COUNT(U72:AB72)) -> 8 | D72: =ROUNDUP( MAX( IF(P72,100, IF(O72,80, IF(N72,70, IF(M72,60, IF(L72,55, IF(K72,50, IF(J72,45, IF(I72,35, IF(H72,25, 0))))))))), 100 * B72/C72 ) * 10 / 100,0) -> 7 | E72: =SUM(U72, Z72) -> 2 | F72: =SUM(V72, W72, X72) -> 2 | G72: =SUM(Y72, AA72, AB72) -> 1 | H72: =IF(B72>0,1,0) -> 1 | I72: =IF( B72/C72 > 0.2, 1, IF(E72>0, 1, 0) ) -> 1 | J72: =IF( B72/C72 > 0.4, 1, IF( E72=2, 1, IF(AND(E72>0, OR(F72>0, G72>0)), 1, 0 ) )) -> 1 | K72: =IF(B72/C72 > 0.5, 1, IF( E72=2, 1, IF(AND(E72>0, OR(F72>1, G72>0)), 1, 0 ) )) -> 1 | L72: =IF(B72/C72 > 0.6, 1, IF( AND(E72=2, OR(F72>0, G72>0)), 1, 0 ) ) -> 1 | M72: =IF(B72/C72 > 0.7, 1, IF( AND(E72=2, SUM(F72, G72)>1), 1, 0 ) ) -> 1 | N72: =IF(B72/C72 > 0.8, 1, IF( AND(E72=2, SUM(F72, G72)>3), 1, 0 ) ) -> 0 | O72: =IF(B72/C72 > 0.9, 1, 0) -> 0 | P72: =ROUNDDOWN(B72/C72,0) -> 0 | U72: 1 | V72: 1 | W72: 1 | X72: 0 | Y72: 1 | Z72: 1 | AA72: 0 | AB72: 0
B73: =(SUM(U73:AB73)) -> 4 | C73: =(COUNT(U73:AB73)) -> 8 | D73: =ROUNDUP( MAX( IF(P73,100, IF(O73,80, IF(N73,70, IF(M73,60, IF(L73,55, IF(K73,50, IF(J73,45, IF(I73,35, IF(H73,25, 0))))))))), 100 * B73/C73 ) * 10 / 100,0) -> 6 | E73: =SUM(U73, Z73) -> 2 | F73: =SUM(V73, W73, X73) -> 2 | G73: =SUM(Y73, AA73, AB73) -> 0 | H73: =IF(B73>0,1,0) -> 1 | I73: =IF( B73/C73 > 0.2, 1, IF(E73>0, 1, 0) ) -> 1 | J73: =IF( B73/C73 > 0.4, 1, IF( E73=2, 1, IF(AND(E73>0, OR(F73>0, G73>0)), 1, 0 ) )) -> 1 | K73: =IF(B73/C73 > 0.5, 1, IF( E73=2, 1, IF(AND(E73>0, OR(F73>1, G73>0)), 1, 0 ) )) -> 1 | L73: =IF(B73/C73 > 0.6, 1, IF( AND(E73=2, OR(F73>0, G73>0)), 1, 0 ) ) -> 1 | M73: =IF(B73/C73 > 0.7, 1, IF( AND(E73=2, SUM(F73, G73)>1), 1, 0 ) ) -> 1 | N73: =IF(B73/C73 > 0.8, 1, IF( AND(E73=2, SUM(F73, G73)>3), 1, 0 ) ) -> 0 | O73: =IF(B73/C73 > 0.9, 1, 0) -> 0 | P73: =ROUNDDOWN(B73/C73,0) -> 0 | U73: 1 | V73: 0 | W73: 1 | X73: 1 | Y73: 0 | Z73: 1 | AA73: 0 | AB73: 0
...

Sheet Summary
C5: /100 | D5: =#REF! -> #REF! | E5: ='Task 2a - Mitigating the Proble'!D215 -> /10 | F5: =#REF! -> #REF! | G5: =#REF! -> #REF! | H5: =#REF! -> #REF!
A6: Marker | B6: Student UUN | C6: Total | D6: Task 1 | E6: Task 2a | F6: Task 2b | G6: Task 2c | H6: Task 3
A7: =#REF! -> #REF! | B7: =#REF! -> #REF! | C7: =SUM(D7:H7) -> #REF! | D7: =#REF! -> #REF! | E7: ='Task 2a - Mitigating the Proble'!D7 -> 7 | F7: =#REF! -> #REF! | G7: =#REF! -> #REF! | H7: =#REF! -> #REF!
A8: =#REF! -> #REF! | B8: =#REF! -> #REF! | C8: 50 | D8: =#REF! -> #REF! | E8: ='Task 2a - Mitigating the Proble'!D8 -> 5 | F8: =#REF! -> #REF! | G8: =#REF! -> #REF! | H8: =#REF! -> #REF! | J8: Was 47. Edited for effort.
A9: =#REF! -> #REF! | B9: =#REF! -> #REF! | C9: =SUM(D9:H9) -> #REF! | D9: =#REF! -> #REF! | E9: ='Task 2a - Mitigating the Proble'!D9 -> 6 | F9: =#REF! -> #REF! | G9: =#REF! -> #REF! | H9: =#REF! -> #REF!
A10: =#REF! -> #REF! | B10: =#REF! -> #REF! | C10: =SUM(D10:H10) -> #REF! | D10: =#REF! -> #REF! | E10: ='Task 2a - Mitigating the Proble'!D10 -> 5 | F10: =#REF! -> #REF! | G10: =#REF! -> #REF! | H10: =#REF! -> #REF!
A11: =#REF! -> #REF! | B11: =#REF! -> #REF! | C11: =SUM(D11:H11) -> #REF! | D11: =#REF! -> #REF! | E11: ='Task 2a - Mitigating the Proble'!D11 -> 6 | F11: =#REF! -> #REF! | G11: =#REF! -> #REF! | H11: =#REF! -> #REF!
A12: =#REF! -> #REF! | B12: =#REF! -> #REF! | C12: =SUM(D12:H12) -> #REF! | D12: =#REF! -> #REF! | E12: ='Task 2a - Mitigating the Proble'!D12 -> 7 | F12: =#REF! -> #REF! | G12: =#REF! -> #REF! | H12: =#REF! -> #REF!
A13: =#REF! -> #REF! | B13: =#REF! -> #REF! | C13: =SUM(D13:H13) -> #REF! | D13: =#REF! -> #REF! | E13: ='Task 2a - Mitigating the Proble'!D13 -> 7 | F13: =#REF! -> #REF! | G13: =#REF! -> #REF! | H13: =#REF! -> #REF!
A14: =#REF! -> #REF! | B14: =#REF! -> #REF! | C14: =SUM(D14:H14) -> #REF! | D14: =#REF! -> #REF! | E14: ='Task 2a - Mitigating the Proble'!D14 -> 5 | F14: =#REF! -> #REF! | G14: =#REF! -> #REF! | H14: =#REF! -> #REF!
A15: =#REF! -> #REF! | B15: =#REF! -> #REF! | C15: =SUM(D15:H15) -> #REF! | D15: =#REF! -> #REF! | E15: ='Task 2a - Mitigating the Proble'!D15 -> 5 | F15: =#REF! -> #REF! | G15: =#REF! -> #REF! | H15: =#REF! -> #REF!
A16: =#REF! -> #REF! | B16: =#REF! -> #REF! | C16: =SUM(D16:H16) -> #REF! | D16: =#REF! -> #REF! | E16: ='Task 2a - Mitigating the Proble'!D16 -> 6 | F16: =#REF! -> #REF! | G16: =#REF! -> #REF! | H16: =#REF! -> #REF!
A17: =#REF! -> #REF! | B17: =#REF! -> #REF! | C17: 40 | D17: =#REF! -> #REF! | E17: ='Task 2a - Mitigating the Proble'!D17 -> 5 | F17: =#REF! -> #REF! | G17: =#REF! -> #REF! | H17: =#REF! -> #REF! | J17: Was 24. Edited for effort.
A18: =#REF! -> #REF! | B18: =#REF! -> #REF! | C18: =SUM(D18:H18) -> #REF! | D18: =#REF! -> #REF! | E18: ='Task 2a - Mitigating the Proble'!D18 -> 7 | F18: =#REF! -> #REF! | G18: =#REF! -> #REF! | H18: =#REF! -> #REF!
A19: =#REF! -> #REF! | B19: =#REF! -> #REF! | C19: =SUM(D19:H19) -> #REF! | D19: =#REF! -> #REF! | E19: ='Task 2a - Mitigating the Proble'!D19 -> 9 | F19: =#REF! -> #REF! | G19: =#REF! -> #REF! | H19: =#REF! -> #REF!
A20: =#REF! -> #REF! | B20: =#REF! -> #REF! | C20: =SUM(D20:H20) -> #REF! | D20: =#REF! -> #REF! | E20: ='Task 2a - Mitigating the Proble'!D20 -> 6 | F20: =#REF! -> #REF! | G20: =#REF! -> #REF! | H20: =#REF! -> #REF!
A21: =#REF! -> #REF! | B21: =#REF! -> #REF! | C21: =SUM(D21:H21) -> #REF! | D21: =#REF! -> #REF! | E21: ='Task 2a - Mitigating the Proble'!D21 -> 7 | F21: =#REF! -> #REF! | G21: =#REF! -> #REF! | H21: =#REF! -> #REF!
A22: =#REF! -> #REF! | B22: =#REF! -> #REF! | C22: =SUM(D22:H22) -> #REF! | D22: =#REF! -> #REF! | E22: ='Task 2a - Mitigating the Proble'!D22 -> 7 | F22: =#REF! -> #REF! | G22: =#REF! -> #REF! | H22: =#REF! -> #REF!
A23: =#REF! -> #REF! | B23: =#REF! -> #REF! | C23: =SUM(D23:H23) -> #REF! | D23: =#REF! -> #REF! | E23: ='Task 2a - Mitigating the Proble'!D23 -> 6 | F23: =#REF! -> #REF! | G23: =#REF! -> #REF! | H23: =#REF! -> #REF!
A24: =#REF! -> #REF! | B24: =#REF! -> #REF! | C24: =SUM(D24:H24) -> #REF! | D24: =#REF! -> #REF! | E24: ='Task 2a - Mitigating the Proble'!D24 -> 6 | F24: =#REF! -> #REF! | G24: =#REF! -> #REF! | H24: =#REF! -> #REF!
A25: =#REF! -> #REF! | B25: =#REF! -> #REF! | C25: =SUM(D25:H25) -> #REF! | D25: =#REF! -> #REF! | E25: ='Task 2a - Mitigating the Proble'!D25 -> 5 | F25: =#REF! -> #REF! | G25: =#REF! -> #REF! | H25: =#REF! -> #REF!
A26: =#REF! -> #REF! | B26: =#REF! -> #REF! | C26: 50 | D26: =#REF! -> #REF! | E26: ='Task 2a - Mitigating the Proble'!D26 -> 6 | F26: =#REF! -> #REF! | G26: =#REF! -> #REF! | H26: =#REF! -> #REF! | J26: Was 45. Edited for effort.
A27: =#REF! -> #REF! | B27: =#REF! -> #REF! | C27: =SUM(D27:H27) -> #REF! | D27: =#REF! -> #REF! | E27: ='Task 2a - Mitigating the Proble'!D27 -> 6 | F27: =#REF! -> #REF! | G27: =#REF! -> #REF! | H27: =#REF! -> #REF!
A28: =#REF! -> #REF! | B28: =#REF! -> #REF! | C28: =SUM(D28:H28) -> #REF! | D28: =#REF! -> #REF! | E28: ='Task 2a - Mitigating the Proble'!D28 -> 5 | F28: =#REF! -> #REF! | G28: =#REF! -> #REF! | H28: =#REF! -> #REF!
A29: =#REF! -> #REF! | B29: =#REF! -> #REF! | C29: =SUM(D29:H29) -> #REF! | D29: =#REF! -> #REF! | E29: ='Task 2a - Mitigating the Proble'!D29 -> 7 | F29: =#REF! -> #REF! | G29: =#REF! -> #REF! | H29: =#REF! -> #REF!
A30: =#REF! -> #REF! | B30: =#REF! -> #REF! | C30: =SUM(D30:H30) -> #REF! | D30: =#REF! -> #REF! | E30: ='Task 2a - Mitigating the Proble'!D30 -> 5 | F30: =#REF! -> #REF! | G30: =#REF! -> #REF! | H30: =#REF! -> #REF!
A31: =#REF! -> #REF! | B31: =#REF! -> #REF! | C31: =SUM(D31:H31) -> #REF! | D31: =#REF! -> #REF! | E31: ='Task 2a - Mitigating the Proble'!D31 -> 8 | F31: =#REF! -> #REF! | G31: =#REF! -> #REF! | H31: =#REF! -> #REF!
A32: =#REF! -> #REF! | B32: =#REF! -> #REF! | C32: =SUM(D32:H32) -> #REF! | D32: =#REF! -> #REF! | E32: ='Task 2a - Mitigating the Proble'!D32 -> 6 | F32: =#REF! -> #REF! | G32: =#REF! -> #REF! | H32: =#REF! -> #REF!
A33: =#REF! -> #REF! | B33: =#REF! -> #REF! | C33: =SUM(D33:H33) -> #REF! | D33: =#REF! -> #REF! | E33: ='Task 2a - Mitigating the Proble'!D33 -> 8 | F33: =#REF! -> #REF! | G33: =#REF! -> #REF! | H33: =#REF! -> #REF!
A34: =#REF! -> #REF! | B34: =#REF! -> #REF! | C34: =SUM(D34:H34) -> #REF! | D34: =#REF! -> #REF! | E34: ='Task 2a - Mitigating the Proble'!D34 -> 6 | F34: =#REF! -> #REF! | G34: =#REF! -> #REF! | H34: =#REF! -> #REF!
A35: =#REF! -> #REF! | B35: =#REF! -> #REF! | C35: =SUM(D35:H35) -> #REF! | D35: =#REF! -> #REF! | E35: ='Task 2a - Mitigating the Proble'!D35 -> 7 | F35: =#REF! -> #REF! | G35: =#REF! -> #REF! | H35: =#REF! -> #REF!
A36: =#REF! -> #REF! | B36: =#REF! -> #REF! | C36: 45 | D36: =#REF! -> #REF! | E36: ='Task 2a - Mitigating the Proble'!D36 -> 6 | F36: =#REF! -> #REF! | G36: =#REF! -> #REF! | H36: =#REF! -> #REF! | J36: Was 37. Edited for effort.
A37: =#REF! -> #REF! | B37: =#REF! -> #REF! | C37: =SUM(D37:H37) -> #REF! | D37: =#REF! -> #REF! | E37: ='Task 2a - Mitigating the Proble'!D37 -> 6 | F37: =#REF! -> #REF! | G37: =#REF! -> #REF! | H37: =#REF! -> #REF!
A38: =#REF! -> #REF! | B38: =#REF! -> #REF! | C38: =SUM(D38:H38) -> #REF! | D38: =#REF! -> #REF! | E38: ='Task 2a - Mitigating the Proble'!D38 -> 7 | F38: =#REF! -> #REF! | G38: =#REF! -> #REF! | H38: =#REF! -> #REF!
A39: =#REF! -> #REF! | B39: =#REF! -> #REF! | C39: =SUM(D39:H39) -> #REF! | D39: =#REF! -> #REF! | E39: ='Task 2a - Mitigating the Proble'!D39 -> 7 | F39: =#REF! -> #REF! | G39: =#REF! -> #REF! | H39: =#REF! -> #REF!
A40: =#REF! -> #REF! | B40: =#REF! -> #REF! | C40: =SUM(D40:H40) -> #REF! | D40: =#REF! -> #REF! | E40: ='Task 2a - Mitigating the Proble'!D40 -> 6 | F40: =#REF! -> #REF! | G40: =#REF! -> #REF! | H40: =#REF! -> #REF!
A41: =#REF! -> #REF! | B41: =#REF! -> #REF! | C41: =SUM(D41:H41) -> #REF! | D41: =#REF! -> #REF! | E41: ='Task 2a - Mitigating the Proble'!D41 -> 5 | F41: =#REF! -> #REF! | G41: =#REF! -> #REF! | H41: =#REF! -> #REF!
A42: =#REF! -> #REF! | B42: =#REF! -> #REF! | C42: =SUM(D42:H42) -> #REF! | D42: =#REF! -> #REF! | E42: ='Task 2a - Mitigating the Proble'!D42 -> 7 | F42: =#REF! -> #REF! | G42: =#REF! -> #REF! | H42: =#REF! -> #REF!
A43: =#REF! -> #REF! | B43: =#REF! -> #REF! | C43: =SUM(D43:H43) -> #REF! | D43: =#REF! -> #REF! | E43: ='Task 2a - Mitigating the Proble'!D43 -> 7 | F43: =#REF! -> #REF! | G43: =#REF! -> #REF! | H43: =#REF! -> #REF!
A44: =#REF! -> #REF! | B44: =#REF! -> #REF! | C44: =SUM(D44:H44) -> #REF! | D44: =#REF! -> #REF! | E44: ='Task 2a - Mitigating the Proble'!D44 -> 6 | F44: =#REF! -> #REF! | G44: =#REF! -> #REF! | H44: =#REF! -> #REF!
...

Sheet Collate Feedback
